<robot name = "robot">
    <link name="Link0">
        <inertial>
            <origin xyz="0 0 9.0" rpy="0 0 0"/>
            <mass value="1" />
            <inertia ixx="100" ixy="0" ixz="0" iyy="100" iyz="0" izz="100" />
        </inertial>
        <visual>
            <origin xyz="0 0 9.0" rpy="0 0 0"/>
            <geometry>
                <box size="0.6108869734438016 0.9130110532378982 0.9666063677707588" />
            </geometry>
            <material name="Cyan">
            <color rgba="0 1.0 1.0 1.0"/>
            </material>
        </visual>
        <collision>
            <origin xyz="0 0 9.0" rpy="0 0 0"/>
            <geometry>
                <box size="0.6108869734438016 0.9130110532378982 0.9666063677707588" />
            </geometry>
        </collision>
    </link>
    <joint name="Link0_Link1" type="revolute">
       <parent link="Link0"/>
       <child  link="Link1"/>
       <origin rpy="0 0 0" xyz="-0.3054434867219008 0.04331407641852992 9.303965672510301" />
     <axis xyz="0 1 0"/>
       <limit effort="0.0" lower="-3.14159" upper="3.14159" velocity="0.0"/>
    </joint>
    <joint name="Link0_Link2" type="revolute">
       <parent link="Link0"/>
       <child  link="Link2"/>
       <origin rpy="0 0 0" xyz="-0.18131012206867478 0.4565055266189491 9.289428152630679" />
     <axis xyz="0 0 1"/>
       <limit effort="0.0" lower="-3.14159" upper="3.14159" velocity="0.0"/>
    </joint>
    <link name="Link1">
        <inertial>
            <origin xyz="-0.3649158741300643 0 0" rpy="0 0 0"/>
            <mass value="1" />
            <inertia ixx="100" ixy="0" ixz="0" iyy="100" iyz="0" izz="100" />
        </inertial>
        <visual>
            <origin xyz="-0.3649158741300643 0 0" rpy="0 0 0"/>
            <geometry>
                <box size="0.7298317482601286 0.8988382879679935 0.6839839319154413" />
            </geometry>
            <material name="Green">
            <color rgba="0 1 0 1"/>
            </material>
        </visual>
        <collision>
            <origin xyz="-0.3649158741300643 0 0" rpy="0 0 0"/>
            <geometry>
                <box size="0.7298317482601286 0.8988382879679935 0.6839839319154413" />
            </geometry>
        </collision>
    </link>
    <joint name="Link1_Link6" type="revolute">
       <parent link="Link1"/>
       <child  link="Link6"/>
       <origin rpy="0 0 0" xyz="-0.40506462925689635 0.44941914398399674 -0.07872576673658113" />
     <axis xyz="1 0 0"/>
       <limit effort="0.0" lower="-3.14159" upper="3.14159" velocity="0.0"/>
    </joint>
    <joint name="Link1_Link9" type="revolute">
       <parent link="Link1"/>
       <child  link="Link9"/>
       <origin rpy="0 0 0" xyz="-0.5531342599857746 -0.2841508962065527 -0.3419919659577206" />
     <axis xyz="0 0 1"/>
       <limit effort="0.0" lower="-3.14159" upper="3.14159" velocity="0.0"/>
    </joint>
    <link name="Link2">
        <inertial>
            <origin xyz="0 0.37897720147015124 0" rpy="0 0 0"/>
            <mass value="1" />
            <inertia ixx="100" ixy="0" ixz="0" iyy="100" iyz="0" izz="100" />
        </inertial>
        <visual>
            <origin xyz="0 0.37897720147015124 0" rpy="0 0 0"/>
            <geometry>
                <box size="0.8444218515250481 0.7579544029403025 0.420571580830845" />
            </geometry>
            <material name="Cyan">
            <color rgba="0 1.0 1.0 1.0"/>
            </material>
        </visual>
        <collision>
            <origin xyz="0 0.37897720147015124 0" rpy="0 0 0"/>
            <geometry>
                <box size="0.8444218515250481 0.7579544029403025 0.420571580830845" />
            </geometry>
        </collision>
    </link>
    <joint name="Link2_Link3" type="revolute">
       <parent link="Link2"/>
       <child  link="Link3"/>
       <origin rpy="0 0 0" xyz="0.42221092576252406 0.05236346826659599 0.07516621809888827" />
     <axis xyz="0 0 1"/>
       <limit effort="0.0" lower="-3.14159" upper="3.14159" velocity="0.0"/>
    </joint>
    <joint name="Link2_Link5" type="revolute">
       <parent link="Link2"/>
       <child  link="Link5"/>
       <origin rpy="0 0 0" xyz="-0.4222109257625241 0.6998807066279731 0.14402903741775044" />
     <axis xyz="0 1 0"/>
       <limit effort="0.0" lower="-3.14159" upper="3.14159" velocity="0.0"/>
    </joint>
    <link name="Link3">
        <inertial>
            <origin xyz="0.2916910197275156 0 0" rpy="0 0 0"/>
            <mass value="1" />
            <inertia ixx="100" ixy="0" ixz="0" iyy="100" iyz="0" izz="100" />
        </inertial>
        <visual>
            <origin xyz="0.2916910197275156 0 0" rpy="0 0 0"/>
            <geometry>
                <box size="0.5833820394550312 0.9081128851953352 0.5046868558173903" />
            </geometry>
            <material name="Green">
            <color rgba="0 1 0 1"/>
            </material>
        </visual>
        <collision>
            <origin xyz="0.2916910197275156 0 0" rpy="0 0 0"/>
            <geometry>
                <box size="0.5833820394550312 0.9081128851953352 0.5046868558173903" />
            </geometry>
        </collision>
    </link>
    <joint name="Link3_Link4" type="revolute">
       <parent link="Link3"/>
       <child  link="Link4"/>
       <origin rpy="0 0 0" xyz="0.39874068208772656 -0.4540564425976676 0.01240214406552513" />
     <axis xyz="0 0 1"/>
       <limit effort="0.0" lower="-3.14159" upper="3.14159" velocity="0.0"/>
    </joint>
    <joint name="Link3_Link10" type="revolute">
       <parent link="Link3"/>
       <child  link="Link10"/>
       <origin rpy="0 0 0" xyz="0.4734896112495792 0.3173727081806683 -0.25234342790869513" />
     <axis xyz="0 0 1"/>
       <limit effort="0.0" lower="-3.14159" upper="3.14159" velocity="0.0"/>
    </joint>
    <link name="Link4">
        <inertial>
            <origin xyz="0 -0.45108297521979135 0" rpy="0 0 0"/>
            <mass value="1" />
            <inertia ixx="100" ixy="0" ixz="0" iyy="100" iyz="0" izz="100" />
        </inertial>
        <visual>
            <origin xyz="0 -0.45108297521979135 0" rpy="0 0 0"/>
            <geometry>
                <box size="0.8102172359965896 0.9021659504395827 0.3101475693193326" />
            </geometry>
            <material name="Green">
            <color rgba="0 1 0 1"/>
            </material>
        </visual>
        <collision>
            <origin xyz="0 -0.45108297521979135 0" rpy="0 0 0"/>
            <geometry>
                <box size="0.8102172359965896 0.9021659504395827 0.3101475693193326" />
            </geometry>
        </collision>
    </link>
    <link name="Link5">
        <inertial>
            <origin xyz="-0.12525317068122027 0 0" rpy="0 0 0"/>
            <mass value="1" />
            <inertia ixx="100" ixy="0" ixz="0" iyy="100" iyz="0" izz="100" />
        </inertial>
        <visual>
            <origin xyz="-0.12525317068122027 0 0" rpy="0 0 0"/>
            <geometry>
                <box size="0.25050634136244054 0.9097462559682401 0.9827854760376531" />
            </geometry>
            <material name="Green">
            <color rgba="0 1 0 1"/>
            </material>
        </visual>
        <collision>
            <origin xyz="-0.12525317068122027 0 0" rpy="0 0 0"/>
            <geometry>
                <box size="0.25050634136244054 0.9097462559682401 0.9827854760376531" />
            </geometry>
        </collision>
    </link>
    <joint name="Link5_Link7" type="revolute">
       <parent link="Link5"/>
       <child  link="Link7"/>
       <origin rpy="0 0 0" xyz="-0.25050634136244054 -0.006681734651774935 0.13876618846217176" />
     <axis xyz="0 0 1"/>
       <limit effort="0.0" lower="-3.14159" upper="3.14159" velocity="0.0"/>
    </joint>
    <joint name="Link5_Link8" type="revolute">
       <parent link="Link5"/>
       <child  link="Link8"/>
       <origin rpy="0 0 0" xyz="-0.020806751610003116 0.2668513970690405 0.4913927380188265" />
     <axis xyz="0 0 1"/>
       <limit effort="0.0" lower="-3.14159" upper="3.14159" velocity="0.0"/>
    </joint>
    <link name="Link6">
        <inertial>
            <origin xyz="0 0.37790210207861197 0" rpy="0 0 0"/>
            <mass value="1" />
            <inertia ixx="100" ixy="0" ixz="0" iyy="100" iyz="0" izz="100" />
        </inertial>
        <visual>
            <origin xyz="0 0.37790210207861197 0" rpy="0 0 0"/>
            <geometry>
                <box size="0.28183784439970383 0.7558042041572239 0.6183689966753316" />
            </geometry>
            <material name="Green">
            <color rgba="0 1 0 1"/>
            </material>
        </visual>
        <collision>
            <origin xyz="0 0.37790210207861197 0" rpy="0 0 0"/>
            <geometry>
                <box size="0.28183784439970383 0.7558042041572239 0.6183689966753316" />
            </geometry>
        </collision>
    </link>
    <link name="Link7">
        <inertial>
            <origin xyz="-0.3918992945173863 0 0" rpy="0 0 0"/>
            <mass value="1" />
            <inertia ixx="100" ixy="0" ixz="0" iyy="100" iyz="0" izz="100" />
        </inertial>
        <visual>
            <origin xyz="-0.3918992945173863 0 0" rpy="0 0 0"/>
            <geometry>
                <box size="0.7837985890347726 0.30331272607892745 0.4765969541523558" />
            </geometry>
            <material name="Cyan">
            <color rgba="0 1.0 1.0 1.0"/>
            </material>
        </visual>
        <collision>
            <origin xyz="-0.3918992945173863 0 0" rpy="0 0 0"/>
            <geometry>
                <box size="0.7837985890347726 0.30331272607892745 0.4765969541523558" />
            </geometry>
        </collision>
    </link>
    <link name="Link8">
        <inertial>
            <origin xyz="0 0 0.1302461551959797" rpy="0 0 0"/>
            <mass value="1" />
            <inertia ixx="100" ixy="0" ixz="0" iyy="100" iyz="0" izz="100" />
        </inertial>
        <visual>
            <origin xyz="0 0 0.1302461551959797" rpy="0 0 0"/>
            <geometry>
                <box size="0.47700977655271704 0.8653099277716401 0.2604923103919594" />
            </geometry>
            <material name="Green">
            <color rgba="0 1 0 1"/>
            </material>
        </visual>
        <collision>
            <origin xyz="0 0 0.1302461551959797" rpy="0 0 0"/>
            <geometry>
                <box size="0.47700977655271704 0.8653099277716401 0.2604923103919594" />
            </geometry>
        </collision>
    </link>
    <link name="Link9">
        <inertial>
            <origin xyz="0 0 -0.20246706872520714" rpy="0 0 0"/>
            <mass value="1" />
            <inertia ixx="100" ixy="0" ixz="0" iyy="100" iyz="0" izz="100" />
        </inertial>
        <visual>
            <origin xyz="0 0 -0.20246706872520714" rpy="0 0 0"/>
            <geometry>
                <box size="0.25891675029296335 0.5112747213686085 0.4049341374504143" />
            </geometry>
            <material name="Green">
            <color rgba="0 1 0 1"/>
            </material>
        </visual>
        <collision>
            <origin xyz="0 0 -0.20246706872520714" rpy="0 0 0"/>
            <geometry>
                <box size="0.25891675029296335 0.5112747213686085 0.4049341374504143" />
            </geometry>
        </collision>
    </link>
    <joint name="Link9_Link11" type="revolute">
       <parent link="Link9"/>
       <child  link="Link11"/>
       <origin rpy="0 0 0" xyz="-0.12526158663808387 -0.11706250349381109 -0.4049341374504143" />
     <axis xyz="0 1 0"/>
       <limit effort="0.0" lower="-3.14159" upper="3.14159" velocity="0.0"/>
    </joint>
    <link name="Link10">
        <inertial>
            <origin xyz="0 0 -0.21708591772689184" rpy="0 0 0"/>
            <mass value="1" />
            <inertia ixx="100" ixy="0" ixz="0" iyy="100" iyz="0" izz="100" />
        </inertial>
        <visual>
            <origin xyz="0 0 -0.21708591772689184" rpy="0 0 0"/>
            <geometry>
                <box size="0.47214271545271336 0.1007012080683658 0.4341718354537837" />
            </geometry>
            <material name="Cyan">
            <color rgba="0 1.0 1.0 1.0"/>
            </material>
        </visual>
        <collision>
            <origin xyz="0 0 -0.21708591772689184" rpy="0 0 0"/>
            <geometry>
                <box size="0.47214271545271336 0.1007012080683658 0.4341718354537837" />
            </geometry>
        </collision>
    </link>
    <link name="Link11">
        <inertial>
            <origin xyz="0 0 -0.007020850082009478" rpy="0 0 0"/>
            <mass value="1" />
            <inertia ixx="100" ixy="0" ixz="0" iyy="100" iyz="0" izz="100" />
        </inertial>
        <visual>
            <origin xyz="0 0 -0.007020850082009478" rpy="0 0 0"/>
            <geometry>
                <box size="0.8050278270130223 0.5486993038355893 0.014041700164018955" />
            </geometry>
            <material name="Cyan">
            <color rgba="0 1.0 1.0 1.0"/>
            </material>
        </visual>
        <collision>
            <origin xyz="0 0 -0.007020850082009478" rpy="0 0 0"/>
            <geometry>
                <box size="0.8050278270130223 0.5486993038355893 0.014041700164018955" />
            </geometry>
        </collision>
    </link>
</robot>